Workbook

Sheet calc
H1: Speedups (min) | P1: Formation | Q1: Infantry | R1: 0.5
C2: Bread | D2: Wood | E2: Stone | F2: Iron | G2: True Gold | H2: General | I2: Construction | J2: Train | K2: Healing | Q2: Cavalry | R2: 0.2
B3: I have | C3: 536550000 | D3: 500000000 | E3: 127000000 | F3: 25000000 | G3: 800 | H3: 62250 | I3: 11881 | J3: 17401 | K3: 42469 | Q3: Archers | R3: 0.3
B5: I gather | C5: 15 | D5: 15 | E5: 10 | F5: 30 | G5: =_xlfn.CONCAT(SUM(C5:F5),"/",Q14," trips") -> 70/70 trips | P5: Gathering
B6: Gathering output | C6: =C5*Q6 -> 210000000 | D6: =D5*Q7 -> 210000000 | E6: =E5*Q8 -> 28000000 | F6: =F5*Q9 -> 21000000 | P6: Bread | Q6: 14000000
P7: Wood | Q7: 14000000
P8: Stone | Q8: 2800000
B9: Production output (from overview) | C9: 94300 | D9: 36500 | E9: 7600 | F9: 1600 | G9: 0 | P9: Iron | Q9: 700000
A10: Output days | B10: 7 | C10: =$B10*C9*140 -> 92414000 | D10: =$B10*D9*435 -> 111142500 | E10: =$B10*E9*435 -> 23142000 | F10: =$B10*F9*435 -> 4872000
P11: gathering days | Q11: 7
A12: To heal T10 troops | B12: 400000 | C12: =$B12*Data!B6 -> 96200000 | D12: =$B12*Data!C6 -> 91160000 | E12: =$B12*Data!D6 -> 18720000 | F12: =$B12*Data!E6 -> 4560000 | K12: =$B12*Data!G6 -> 22634.676 | P12: gathering marches | Q12: 5
A13: To heal T9 troops | B13: 500000 | C13: =$B13*Data!B12 -> 60000000 | D13: =$B13*Data!C12 -> 57100000 | E13: =$B13*Data!D12 -> 11700000 | F13: =$B13*Data!E12 -> 2900000 | K13: =$B13*Data!G12 -> 19995.078 | P13: trips per march | Q13: 2
B14: Healing cost | C14: =C12+C13 -> 156200000 | D14: =D12+D13 -> 1.4826e+08 | E14: =E12+E13 -> 30420000 | F14: =F12+F13 -> 7460000 | K14: =K12+K13 -> 42629.754 | P14: gathering trips total | Q14: =Q12*Q11*Q13 -> 70
A18: Train T10 infantry | B18: 0 | C18: =$B18*Data!B17 -> 0 | D18: =$B18*Data!C17 -> 0 | E18: =$B18*Data!D17 -> 0 | F18: =$B18*Data!E17 -> 0 | J18: =$B18*Data!G17 -> 0 | P18: Healing Speed | Q18: 4.418
A19: Train T10 cavalry | B19: 0 | C19: =$B19*Data!B18 -> 0 | D19: =$B19*Data!C18 -> 0 | E19: =$B19*Data!D18 -> 0 | F19: =$B19*Data!E18 -> 0 | J19: =$B19*Data!G18 -> 0 | P19: Training Speed | Q19: 1.941
A20: Train T10 archers | B20: 0 | C20: =$B20*Data!B19 -> 0 | D20: =$B20*Data!C19 -> 0 | E20: =$B20*Data!D19 -> 0 | F20: =$B20*Data!E19 -> 0 | J20: =$B20*Data!G19 -> 0 | P20: Construction Speed | Q20: 0.642
A21: Train T9 infantry | B21: 0 | C21: =$B21*Data!B23 -> 0 | D21: =$B21*Data!C23 -> 0 | E21: =$B21*Data!D23 -> 0 | F21: =$B21*Data!E23 -> 0 | J21: =$B21*Data!G23 -> 0
A22: Train T9 cavalry | B22: 0 | C22: =$B22*Data!B24 -> 0 | D22: =$B22*Data!C24 -> 0 | E22: =$B22*Data!D24 -> 0 | F22: =$B22*Data!E24 -> 0 | J22: =$B22*Data!G24 -> 0 | P22: Name | Q22: Include | R22: Bread | S22: Wood | T22: Stone | U22: Iron | V22: True Gold | W22: Time (min) | X22: Real time (min) | Z22: Requirements | AC22: d | AD22: h | AE22: m | AF22: s
A23: Train T9 archers | B23: 0 | C23: =$B23*Data!B25 -> 0 | D23: =$B23*Data!C25 -> 0 | E23: =$B23*Data!D25 -> 0 | F23: =$B23*Data!E25 -> 0 | J23: =$B23*Data!G25 -> 0 | P23: Barracks 30 | Q23: y | R23: 100000000 | S23: 100000000 | T23: 21000000 | U23: 5800000 | W23: =6*24*60 + 40 -> 8680 | X23: =W23/(1+Q$20) -> 5286.2363 | Y23: =_xlfn.CONCAT(AC23,"d ",AD23,"h ",AE23,"m ",AF23,"s") -> 3d 16h 6m 0s | AC23: =ROUNDDOWN(X23/60/24,0) -> 3 | AD23: =ROUNDDOWN((X23-60*24*AC23)/60,0) -> 16 | AE23: =ROUNDDOWN((X23-AC23*24*60-AD23*60),0) -> 6 | AF23: =ROUNDDOWN((X23-AC23*24*60-AD23*60-AE23)/60,0) -> 0
A24: Promote T9->T10 infantry | B24: 90000 | C24: =$B24*Data!B30 -> 125460000 | D24: =$B24*Data!C30 -> 94050000 | E24: =$B24*Data!D30 -> 21960000 | F24: =$B24*Data!E30 -> 4590000 | J24: =$B24*Data!G30 -> 10691.715 | P24: Range 30 | Q24: y | R24: 100000000 | S24: 100000000 | T24: 21000000 | U24: 5800000 | W24: =6*24*60 + 40 -> 8680 | X24: =W24/(1+Q$20) -> 5286.2363 | Y24: =_xlfn.CONCAT(AC24,"d ",AD24,"h ",AE24,"m ",AF24,"s") -> 3d 16h 6m 0s | AC24: =ROUNDDOWN(X24/60/24,0) -> 3 | AD24: =ROUNDDOWN((X24-60*24*AC24)/60,0) -> 16 | AE24: =ROUNDDOWN((X24-AC24*24*60-AD24*60),0) -> 6 | AF24: =ROUNDDOWN((X24-AC24*24*60-AD24*60-AE24)/60,0) -> 0
A25: Promote T9->T10 cavalry | B25: 10000 | C25: =$B25*Data!B31 -> 12200000 | D25: =$B25*Data!C31 -> 11500000 | E25: =$B25*Data!D31 -> 2370000 | F25: =$B25*Data!E31 -> 540000 | J25: =$B25*Data!G31 -> 1187.9684 | P25: Stable 30 | R25: 100000000 | S25: 100000000 | T25: 21000000 | U25: 5800000 | W25: =6*24*60 + 40 -> 8680 | X25: =W25/(1+Q$20) -> 5286.2363 | Y25: =_xlfn.CONCAT(AC25,"d ",AD25,"h ",AE25,"m ",AF25,"s") -> 3d 16h 6m 0s | AC25: =ROUNDDOWN(X25/60/24,0) -> 3 | AD25: =ROUNDDOWN((X25-60*24*AC25)/60,0) -> 16 | AE25: =ROUNDDOWN((X25-AC25*24*60-AD25*60),0) -> 6 | AF25: =ROUNDDOWN((X25-AC25*24*60-AD25*60-AE25)/60,0) -> 0
A26: Promote T9->T10 archers | B26: 90000 | C26: =$B26*Data!B32 -> 78390000 | D26: =$B26*Data!C32 -> 116010000 | E26: =$B26*Data!D32 -> 19440000 | F26: =$B26*Data!E32 -> 6300000 | J26: =$B26*Data!G32 -> 10691.715 | P26: Embassy 30 | Q26: y | R26: 60000000 | S26: 60000000 | T26: 12000000 | U26: 3000000 | W26: =26*24*60+ 12*60 +32 -> 38192 | X26: =W26/(1+Q$20) -> 23259.44 | Y26: =_xlfn.CONCAT(AC26,"d ",AD26,"h ",AE26,"m ",AF26,"s") -> 16d 3h 39m 0s | AC26: =ROUNDDOWN(X26/60/24,0) -> 16 | AD26: =ROUNDDOWN((X26-60*24*AC26)/60,0) -> 3 | AE26: =ROUNDDOWN((X26-AC26*24*60-AD26*60),0) -> 39 | AF26: =ROUNDDOWN((X26-AC26*24*60-AD26*60-AE26)/60,0) -> 0
B27: Total | C27: =SUM(C18:C26) -> 216050000 | D27: =SUM(D18:D26) -> 221560000 | E27: =SUM(E18:E26) -> 43770000 | F27: =SUM(F18:F26) -> 11430000 | J27: =SUM(J18:J26) -> 22571.399 | P27: Academy 30 | Q27: y | R27: 120000000 | S27: 120000000 | T27: 24000000 | U27: 6000000 | W27: =6*24*60+40 -> 8680 | X27: =W27/(1+Q$20) -> 5286.2363 | Y27: =_xlfn.CONCAT(AC27,"d ",AD27,"h ",AE27,"m ",AF27,"s") -> 3d 16h 6m 0s | AC27: =ROUNDDOWN(X27/60/24,0) -> 3 | AD27: =ROUNDDOWN((X27-60*24*AC27)/60,0) -> 16 | AE27: =ROUNDDOWN((X27-AC27*24*60-AD27*60),0) -> 6 | AF27: =ROUNDDOWN((X27-AC27*24*60-AD27*60-AE27)/60,0) -> 0
P28: Town Center 30 | R28: 300000000 | S28: 300000000 | T28: 60000000 | U28: 15000000 | W28: =40*24*60+ 4*60+ 27 -> 57867 | X28: =W28/(1+Q$20) -> 35241.778 | Y28: =_xlfn.CONCAT(AC28,"d ",AD28,"h ",AE28,"m ",AF28,"s") -> 24d 11h 21m 0s | Z28: Embassy 29, Range 29 | AC28: =ROUNDDOWN(X28/60/24,0) -> 24 | AD28: =ROUNDDOWN((X28-60*24*AC28)/60,0) -> 11 | AE28: =ROUNDDOWN((X28-AC28*24*60-AD28*60),0) -> 21 | AF28: =ROUNDDOWN((X28-AC28*24*60-AD28*60-AE28)/60,0) -> 0
P29: Town Center 30-1 | Q29: y | R29: 67000000 | S29: 67000000 | T29: 13000000 | U29: 3300000 | V29: 132 | W29: =7*24*60 -> 10080 | X29: =W29/(1+Q$20) -> 6138.8551 | Y29: =_xlfn.CONCAT(AC29,"d ",AD29,"h ",AE29,"m ",AF29,"s") -> 4d 6h 18m 0s | Z29: Embassy 30, Academy 30 | AC29: =ROUNDDOWN(X29/60/24,0) -> 4 | AD29: =ROUNDDOWN((X29-60*24*AC29)/60,0) -> 6 | AE29: =ROUNDDOWN((X29-AC29*24*60-AD29*60),0) -> 18 | AF29: =ROUNDDOWN((X29-AC29*24*60-AD29*60-AE29)/60,0) -> 0
P30: Town Center 30-2 | R30: 67000000 | S30: 67000000 | T30: 13000000 | U30: 3300000 | V30: 132 | W30: =7*24*60 -> 10080 | X30: =W30/(1+Q$20) -> 6138.8551 | Y30: =_xlfn.CONCAT(AC30,"d ",AD30,"h ",AE30,"m ",AF30,"s") -> 4d 6h 18m 0s | Z30: Embassy 30, Academy 30 | AC30: =ROUNDDOWN(X30/60/24,0) -> 4 | AD30: =ROUNDDOWN((X30-60*24*AC30)/60,0) -> 6 | AE30: =ROUNDDOWN((X30-AC30*24*60-AD30*60),0) -> 18 | AF30: =ROUNDDOWN((X30-AC30*24*60-AD30*60-AE30)/60,0) -> 0
H31: Time (min) | P31: Town Center 30-3 | R31: 67000000 | S31: 67000000 | T31: 13000000 | U31: 3300000 | V31: 132 | W31: =7*24*60 -> 10080 | X31: =W31/(1+Q$20) -> 6138.8551 | Y31: =_xlfn.CONCAT(AC31,"d ",AD31,"h ",AE31,"m ",AF31,"s") -> 4d 6h 18m 0s | Z31: Embassy 30, Academy 30 | AC31: =ROUNDDOWN(X31/60/24,0) -> 4 | AD31: =ROUNDDOWN((X31-60*24*AC31)/60,0) -> 6 | AE31: =ROUNDDOWN((X31-AC31*24*60-AD31*60),0) -> 18 | AF31: =ROUNDDOWN((X31-AC31*24*60-AD31*60-AE31)/60,0) -> 0
B32: Summary | C32: Bread | D32: Wood | E32: Stone | F32: Iron | G32: True Gold | H32: General | I32: Construction | J32: Train | K32: Healing | P32: Town Center 30-4 | R32: 67000000 | S32: 67000000 | T32: 13000000 | U32: 3300000 | V32: 132 | W32: =7*24*60 -> 10080 | X32: =W32/(1+Q$20) -> 6138.8551 | Y32: =_xlfn.CONCAT(AC32,"d ",AD32,"h ",AE32,"m ",AF32,"s") -> 4d 6h 18m 0s | Z32: Embassy 30, Academy 30 | AC32: =ROUNDDOWN(X32/60/24,0) -> 4 | AD32: =ROUNDDOWN((X32-60*24*AC32)/60,0) -> 6 | AE32: =ROUNDDOWN((X32-AC32*24*60-AD32*60),0) -> 18 | AF32: =ROUNDDOWN((X32-AC32*24*60-AD32*60-AE32)/60,0) -> 0
B33: I have | C33: =C3 -> 536550000 | D33: =D3 -> 500000000 | E33: =E3 -> 127000000 | F33: =F3 -> 25000000 | G33: =G3 -> 800 | H33: =H3 -> 62250 | I33: =I3 -> 11881 | J33: =J3 -> 17401 | K33: =K3 -> 42469 | P33: Town Center TG1 | R33: 67000000 | S33: 67000000 | T33: 13000000 | U33: 3300000 | V33: 132 | W33: =7*24*60 -> 10080 | X33: =W33/(1+Q$20) -> 6138.8551 | Y33: =_xlfn.CONCAT(AC33,"d ",AD33,"h ",AE33,"m ",AF33,"s") -> 4d 6h 18m 0s | Z33: Embassy 30, Academy 30 | AC33: =ROUNDDOWN(X33/60/24,0) -> 4 | AD33: =ROUNDDOWN((X33-60*24*AC33)/60,0) -> 6 | AE33: =ROUNDDOWN((X33-AC33*24*60-AD33*60),0) -> 18 | AF33: =ROUNDDOWN((X33-AC33*24*60-AD33*60-AE33)/60,0) -> 0
B34: I gather | C34: =C6 -> 210000000 | D34: =D6 -> 210000000 | E34: =E6 -> 28000000 | F34: =F6 -> 21000000 | P34: Embassy 30-1 | R34: 13000000 | S34: 13000000 | T34: 2700000 | U34: 670000 | V34: 33 | W34: =4*24*60+ 14*60+ 52 -> 6652 | X34: =W34/(1+Q$20) -> 4051.1571 | Y34: =_xlfn.CONCAT(AC34,"d ",AD34,"h ",AE34,"m ",AF34,"s") -> 2d 19h 31m 0s | Z34: Town Center TG1 | AC34: =ROUNDDOWN(X34/60/24,0) -> 2 | AD34: =ROUNDDOWN((X34-60*24*AC34)/60,0) -> 19 | AE34: =ROUNDDOWN((X34-AC34*24*60-AD34*60),0) -> 31 | AF34: =ROUNDDOWN((X34-AC34*24*60-AD34*60-AE34)/60,0) -> 0
B35: I farm | C35: =C10 -> 92414000 | D35: =D10 -> 111142500 | E35: =E10 -> 23142000 | F35: =F10 -> 4872000 | G35: =G9 -> 0 | P35: Embassy 30-2 | R35: 13000000 | S35: 13000000 | T35: 2700000 | U35: 670000 | V35: 33 | W35: =4*24*60+ 14*60+ 52 -> 6652 | X35: =W35/(1+Q$20) -> 4051.1571 | Y35: =_xlfn.CONCAT(AC35,"d ",AD35,"h ",AE35,"m ",AF35,"s") -> 2d 19h 31m 0s | Z35: Town Center TG1 | AC35: =ROUNDDOWN(X35/60/24,0) -> 2 | AD35: =ROUNDDOWN((X35-60*24*AC35)/60,0) -> 19 | AE35: =ROUNDDOWN((X35-AC35*24*60-AD35*60),0) -> 31 | AF35: =ROUNDDOWN((X35-AC35*24*60-AD35*60-AE35)/60,0) -> 0
B36: Building costs | C36: =R72 -> 447000000 | D36: =S72 -> 447000000 | E36: =T72 -> 91000000 | F36: =U72 -> 23900000 | G36: =V72 -> 132 | I36: =X72 -> 45257.004 | P36: Embassy 30-3 | R36: 13000000 | S36: 13000000 | T36: 2700000 | U36: 670000 | V36: 33 | W36: =4*24*60+ 14*60+ 52 -> 6652 | X36: =W36/(1+Q$20) -> 4051.1571 | Y36: =_xlfn.CONCAT(AC36,"d ",AD36,"h ",AE36,"m ",AF36,"s") -> 2d 19h 31m 0s | Z36: Town Center TG1 | AC36: =ROUNDDOWN(X36/60/24,0) -> 2 | AD36: =ROUNDDOWN((X36-60*24*AC36)/60,0) -> 19 | AE36: =ROUNDDOWN((X36-AC36*24*60-AD36*60),0) -> 31 | AF36: =ROUNDDOWN((X36-AC36*24*60-AD36*60-AE36)/60,0) -> 0
B37: Training/Promoting costs | C37: =C27 -> 216050000 | D37: =D27 -> 221560000 | E37: =E27 -> 43770000 | F37: =F27 -> 11430000 | J37: =SUM(J18:J27) -> 45142.798 | P37: Embassy 30-4 | R37: 13000000 | S37: 13000000 | T37: 2700000 | U37: 670000 | V37: 33 | W37: =4*24*60+ 14*60+ 52 -> 6652 | X37: =W37/(1+Q$20) -> 4051.1571 | Y37: =_xlfn.CONCAT(AC37,"d ",AD37,"h ",AE37,"m ",AF37,"s") -> 2d 19h 31m 0s | Z37: Town Center TG1 | AC37: =ROUNDDOWN(X37/60/24,0) -> 2 | AD37: =ROUNDDOWN((X37-60*24*AC37)/60,0) -> 19 | AE37: =ROUNDDOWN((X37-AC37*24*60-AD37*60),0) -> 31 | AF37: =ROUNDDOWN((X37-AC37*24*60-AD37*60-AE37)/60,0) -> 0
B38: Healing costs | C38: =C14 -> 156200000 | D38: =D14 -> 1.4826e+08 | E38: =E14 -> 30420000 | F38: =F14 -> 7460000 | K38: =K14 -> 42629.754 | P38: Embassy TG1 | R38: 13000000 | S38: 13000000 | T38: 2700000 | U38: 670000 | V38: 33 | W38: =4*24*60+ 14*60+ 52 -> 6652 | X38: =W38/(1+Q$20) -> 4051.1571 | Y38: =_xlfn.CONCAT(AC38,"d ",AD38,"h ",AE38,"m ",AF38,"s") -> 2d 19h 31m 0s | Z38: Town Center TG1 | AC38: =ROUNDDOWN(X38/60/24,0) -> 2 | AD38: =ROUNDDOWN((X38-60*24*AC38)/60,0) -> 19 | AE38: =ROUNDDOWN((X38-AC38*24*60-AD38*60),0) -> 31 | AF38: =ROUNDDOWN((X38-AC38*24*60-AD38*60-AE38)/60,0) -> 0
P39: Stable 30-1 | R39: 23000000 | S39: 23000000 | T39: 4700000 | U39: 1100000 | V39: 59 | W39: =1*24*60+ 1*60+ 12 -> 1512 | X39: =W39/(1+Q$20) -> 920.82826 | Y39: =_xlfn.CONCAT(AC39,"d ",AD39,"h ",AE39,"m ",AF39,"s") -> 0d 15h 20m 0s | Z39: Town Center TG1 | AC39: =ROUNDDOWN(X39/60/24,0) -> 0 | AD39: =ROUNDDOWN((X39-60*24*AC39)/60,0) -> 15 | AE39: =ROUNDDOWN((X39-AC39*24*60-AD39*60),0) -> 20 | AF39: =ROUNDDOWN((X39-AC39*24*60-AD39*60-AE39)/60,0) -> 0
B40: Total IN (M) | C40: =SUM(C33:C35) -> 838964000 | D40: =SUM(D33:D35) -> 821142500 | E40: =SUM(E33:E35) -> 178142000 | F40: =SUM(F33:F35) -> 50872000 | G40: =SUM(G33:G35) -> 800 | H40: =H33 -> 62250 | I40: =I33 -> 11881 | J40: =J33 -> 17401 | P40: Stable 30-2 | R40: 23000000 | S40: 23000000 | T40: 4700000 | U40: 1100000 | V40: 59 | W40: =1*24*60+ 1*60+ 12 -> 1512 | X40: =W40/(1+Q$20) -> 920.82826 | Y40: =_xlfn.CONCAT(AC40,"d ",AD40,"h ",AE40,"m ",AF40,"s") -> 0d 15h 20m 0s | Z40: Town Center TG1 | AC40: =ROUNDDOWN(X40/60/24,0) -> 0 | AD40: =ROUNDDOWN((X40-60*24*AC40)/60,0) -> 15 | AE40: =ROUNDDOWN((X40-AC40*24*60-AD40*60),0) -> 20 | AF40: =ROUNDDOWN((X40-AC40*24*60-AD40*60-AE40)/60,0) -> 0
B41: Total OUT (M) | C41: =SUM(C36:C38) -> 819250000 | D41: =SUM(D36:D38) -> 816820000 | E41: =SUM(E36:E38) -> 165190000 | F41: =SUM(F36:F38) -> 42790000 | G41: =SUM(G36:G38) -> 132 | I41: =I36 -> 45257.004 | J41: =J37 -> 45142.798 | K41: =K38 -> 42629.754 | P41: Stable 30-3 | R41: 23000000 | S41: 23000000 | T41: 4700000 | U41: 1100000 | V41: 59 | W41: =1*24*60+ 1*60+ 12 -> 1512 | X41: =W41/(1+Q$20) -> 920.82826 | Y41: =_xlfn.CONCAT(AC41,"d ",AD41,"h ",AE41,"m ",AF41,"s") -> 0d 15h 20m 0s | Z41: Town Center TG1 | AC41: =ROUNDDOWN(X41/60/24,0) -> 0 | AD41: =ROUNDDOWN((X41-60*24*AC41)/60,0) -> 15 | AE41: =ROUNDDOWN((X41-AC41*24*60-AD41*60),0) -> 20 | AF41: =ROUNDDOWN((X41-AC41*24*60-AD41*60-AE41)/60,0) -> 0
B42: Balance | C42: =C40-C41 -> 19714000 | D42: =D40-D41 -> 4322500 | E42: =E40-E41 -> 12952000 | F42: =F40-F41 -> 8082000 | G42: =G40-G41 -> 668 | H42: with healing | I42: {=SUM(H40:K40-H41:K41)} -> -41497.556 | P42: Stable 30-4 | R42: 23000000 | S42: 23000000 | T42: 4700000 | U42: 1100000 | V42: 59 | W42: =1*24*60+ 1*60+ 12 -> 1512 | X42: =W42/(1+Q$20) -> 920.82826 | Y42: =_xlfn.CONCAT(AC42,"d ",AD42,"h ",AE42,"m ",AF42,"s") -> 0d 15h 20m 0s | Z42: Town Center TG1 | AC42: =ROUNDDOWN(X42/60/24,0) -> 0 | AD42: =ROUNDDOWN((X42-60*24*AC42)/60,0) -> 15 | AE42: =ROUNDDOWN((X42-AC42*24*60-AD42*60),0) -> 20 | AF42: =ROUNDDOWN((X42-AC42*24*60-AD42*60-AE42)/60,0) -> 0
H43: without healing | I43: {=SUM(H40:J40-H41:J41)} -> 1132.198 | P43: Stable TG1 | R43: 23000000 | S43: 23000000 | T43: 4700000 | U43: 1100000 | V43: 59 | W43: =1*24*60+ 1*60+ 12 -> 1512 | X43: =W43/(1+Q$20) -> 920.82826 | Y43: =_xlfn.CONCAT(AC43,"d ",AD43,"h ",AE43,"m ",AF43,"s") -> 0d 15h 20m 0s | Z43: Town Center TG1 | AC43: =ROUNDDOWN(X43/60/24,0) -> 0 | AD43: =ROUNDDOWN((X43-60*24*AC43)/60,0) -> 15 | AE43: =ROUNDDOWN((X43-AC43*24*60-AD43*60),0) -> 20 | AF43: =ROUNDDOWN((X43-AC43*24*60-AD43*60-AE43)/60,0) -> 0
P44: Town Center TG1-1 | R44: 72000000 | S44: 72000000 | T44: 14000000 | U44: 3600000 | V44: 158 | W44: =9*24*60 -> 12960 | X44: =W44/(1+Q$20) -> 7892.8136 | Y44: =_xlfn.CONCAT(AC44,"d ",AD44,"h ",AE44,"m ",AF44,"s") -> 5d 11h 32m 0s | Z44: Embassy TG 1, Stable TG 1 | AC44: =ROUNDDOWN(X44/60/24,0) -> 5 | AD44: =ROUNDDOWN((X44-60*24*AC44)/60,0) -> 11 | AE44: =ROUNDDOWN((X44-AC44*24*60-AD44*60),0) -> 32 | AF44: =ROUNDDOWN((X44-AC44*24*60-AD44*60-AE44)/60,0) -> 0
...

Sheet Data
A1: Healing
A2: 1 T10 | B2: Bread | C2: Wood | D2: Stone | E2: Iron | F2: Original Time (min) | G2: Time (min) | H2: Time
A3: infantry | B3: 279 | C3: 209 | D3: 49 | E3: 10 | F3: =15/60 -> 0.25 | G3: =F3/(1+calc!$Q$18) -> 0.046142488 | H3: =G3/24/60 -> 3.2043394e-05
A4: cavalry | B4: 244 | C4: 230 | D4: 47 | E4: 11 | F4: =15/60 -> 0.25 | G4: =F4/(1+calc!$Q$18) -> 0.046142488 | H4: =G4/24/60 -> 3.2043394e-05
A5: archers | B5: 174 | C5: 258 | D5: 43 | E5: 14 | F5: =15/60 -> 0.25 | G5: =F5/(1+calc!$Q$18) -> 0.046142488 | H5: =G5/24/60 -> 3.2043394e-05
A6: formation | B6: =SUMPRODUCT(B3:B5,calc!$R$1:$R$3) -> 240.5 | C6: =SUMPRODUCT(C3:C5,calc!$R$1:$R$3) -> 227.9 | D6: =SUMPRODUCT(D3:D5,calc!$R$1:$R$3) -> 46.8 | E6: =SUMPRODUCT(E3:E5,calc!$R$1:$R$3) -> 11.4 | F6: =SUMPRODUCT(F3:F5,calc!$R$1:$R$3) -> 0.25 | G6: =F6/calc!$Q$18 -> 0.056586691
A8: 1 T9 | B8: Bread | C8: Wood | D8: Stone | E8: Iron | F8: Original Time (min) | G8: Time (min) | H8: Time
A9: infantry | B9: 139 | C9: 105 | D9: 24 | E9: 5 | F9: =(21+40/60)/100 -> 0.21666667 | G9: =F9/(1+calc!$Q$18) -> 0.039990156 | H9: =G9/24/60 -> 2.7770942e-05
A10: cavalry | B10: 122 | C10: 115 | D10: 24 | E10: 6 | F10: =(21+40/60)/100 -> 0.21666667 | G10: =F10/(1+calc!$Q$18) -> 0.039990156 | H10: =G10/24/60 -> 2.7770942e-05
A11: archers | B11: 87 | C11: 129 | D11: 22 | E11: 7 | F11: =(21+40/60)/100 -> 0.21666667 | G11: =F11/(1+calc!$Q$18) -> 0.039990156 | H11: =G11/24/60 -> 2.7770942e-05
A12: with formation | B12: =SUMPRODUCT(B9:B11,calc!$R$1:$R$3) -> 120 | C12: =SUMPRODUCT(C9:C11,calc!$R$1:$R$3) -> 114.2 | D12: =SUMPRODUCT(D9:D11,calc!$R$1:$R$3) -> 23.4 | E12: =SUMPRODUCT(E9:E11,calc!$R$1:$R$3) -> 5.8 | F12: =SUMPRODUCT(F9:F11,calc!$R$1:$R$3) -> 0.21666667 | G12: =SUMPRODUCT(G9:G11,calc!$R$1:$R$3) -> 0.039990156
B13: =SUMPRODUCT(B9:B11,$H9:$H11) -> 0.0096642878 | C13: =SUMPRODUCT(C9:C11,$H9:$H11) -> 0.0096920587 | D13: =SUMPRODUCT(D9:D11,$H9:$H11) -> 0.0019439659 | E13: =SUMPRODUCT(E9:E11,$H9:$H11) -> 0.00049987695 | F13: =SUMPRODUCT(F9:F11,$H9:$H11) -> 1.8051112e-05 | G13: =SUMPRODUCT(G9:G11,$H9:$H11) -> 3.3316929e-06
A15: Training
A16: 1 T10 | B16: Bread | C16: Wood | D16: Stone | E16: Iron | F16: Original Time (min) | G16: Time (min) | H16: Time
A17: infantry | B17: 2788 | C17: 2091 | D17: 488 | E17: 102 | F17: =2+32/60 -> 2.5333333 | G17: =F17/(1+calc!Q$19) -> 0.86138502 | H17: =G17/24/60 -> 0.00059818404
A18: cavalry | B18: 2440 | C18: 2301 | D18: 474 | E18: 109 | F18: =2+32/60 -> 2.5333333 | G18: =F18/(1+calc!Q$19) -> 0.86138502 | H18: =G18/24/60 -> 0.00059818404
A19: archers | B19: =B25*1.1 -> 959.2 | C19: =C25*1.1 -> 1419 | D19: =D25*1.1 -> 238.7 | E19: =E25*1.1 -> 77 | F19: =2+32/60 -> 2.5333333 | G19: =F19/(1+calc!Q$19) -> 0.86138502 | H19: =G19/24/60 -> 0.00059818404
A20: with formation | B20: =SUMPRODUCT(B17:B19,calc!$R$1:$R$3) -> 2169.76 | C20: =SUMPRODUCT(C17:C19,calc!$R$1:$R$3) -> 1931.4 | D20: =SUMPRODUCT(D17:D19,calc!$R$1:$R$3) -> 410.41 | E20: =SUMPRODUCT(E17:E19,calc!$R$1:$R$3) -> 95.9
A22: 1 T9 | B22: Bread | C22: Wood | D22: Stone | E22: Iron | F22: Original Time (min) | G22: Time (min) | H22: Time
A23: infantry | B23: 1394 | C23: 1046 | D23: 244 | E23: 51 | F23: =2+11/60 -> 2.1833333 | G23: =F23/(1+calc!Q$19) -> 0.74237788 | H23: =G23/24/60 -> 0.00051554019
A24: cavalry | B24: 1220 | C24: 1151 | D24: 237 | E24: 55 | F24: =2+11/60 -> 2.1833333 | G24: =F24/(1+calc!Q$19) -> 0.74237788 | H24: =G24/24/60 -> 0.00051554019
A25: archers | B25: 872 | C25: 1290 | D25: 217 | E25: 70 | F25: =2+11/60 -> 2.1833333 | G25: =F25/(1+calc!Q$19) -> 0.74237788 | H25: =G25/24/60 -> 0.00051554019
A26: with formation | B26: =SUMPRODUCT(B23:B25,calc!$R$1:$R$3) -> 1202.6 | C26: =SUMPRODUCT(C23:C25,calc!$R$1:$R$3) -> 1140.2 | D26: =SUMPRODUCT(D23:D25,calc!$R$1:$R$3) -> 234.5 | E26: =SUMPRODUCT(E23:E25,calc!$R$1:$R$3) -> 57.5
A28: Promotion
A29: 1 T9 -> T10 | B29: Bread | C29: Wood | D29: Stone | E29: Iron | F29: Original Time (min) | G29: Time (min) | H29: Time
A30: infantry | B30: 1394 | C30: 1045 | D30: 244 | E30: 51 | F30: 0.3493815 | G30: =F30/(1+calc!Q$19) -> 0.11879684 | H30: =G30/24/60 -> 8.2497804e-05
A31: cavalry | B31: 1220 | C31: 1150 | D31: 237 | E31: 54 | F31: 0.3493815 | G31: =F31/(1+calc!Q$19) -> 0.11879684 | H31: =G31/24/60 -> 8.2497804e-05
A32: archers | B32: 871 | C32: 1289 | D32: 216 | E32: 70 | F32: 0.3493815 | G32: =F32/(1+calc!Q$19) -> 0.11879684 | H32: =G32/24/60 -> 8.2497804e-05
A33: with formation | B33: =SUMPRODUCT(B30:B32,calc!$R$1:$R$3) -> 1202.3 | C33: =SUMPRODUCT(C30:C32,calc!$R$1:$R$3) -> 1139.2 | D33: =SUMPRODUCT(D30:D32,calc!$R$1:$R$3) -> 234.2 | E33: =SUMPRODUCT(E30:E32,calc!$R$1:$R$3) -> 57.3
